{"topic": "orderbook.200.BTCUSDT", "type": "snapshot", "ts": 1725024600000, "data": {"s": "BTCUSDT", "b": [["60000.0", "1.5"], ["59999.9", "2.0"], ["59999.8", "0.5"], ["59999.7", "1.0"], ["59999.6", "0.8"]], "a": [["60000.1", "1.2"], ["60000.2", "2.0"], ["60000.3", "0.4"], ["60000.4", "1.1"], ["60000.5", "0.9"]], "u": 100, "seq": 9000}}
{"topic": "orderbook.200.BTCUSDT", "type": "delta", "ts": 1725024600100, "data": {"s": "BTCUSDT", "b": [["60000.0", "0"]], "a": [], "u": 101, "seq": 9001}}
{"topic": "orderbook.200.BTCUSDT", "type": "delta", "ts": 1725024600200, "data": {"s": "BTCUSDT", "b": [["59999.5", "3.0"]], "a": [], "u": 102, "seq": 9003}}
{"topic": "orderbook.200.BTCUSDT", "type": "delta", "ts": 1725024600300, "data": {"s": "BTCUSDT", "b": [], "a": [["60000.1", "0"]], "u": 103, "seq": 9004}}
{"topic": "orderbook.200.BTCUSDT", "type": "delta", "ts": 1725024600400, "data": {"s": "BTCUSDT", "b": [], "a": [["60000.6", "1.7"]], "u": 104, "seq": 9008}}
{"topic": "orderbook.200.BTCUSDT", "type": "delta", "ts": 1725024600500, "data": {"s": "BTCUSDT", "b": [["59999.9", "0.25"]], "a": [], "u": 105, "seq": 9010}}
{"topic": "orderbook.200.BTCUSDT", "type": "delta", "ts": 1725024600600, "data": {"s": "BTCUSDT", "b": [["59999.4", "0"]], "a": [["60000.7", "0.3"]], "u": 106, "seq": 9011}}
{"topic": "orderbook.200.BTCUSDT", "type": "delta", "ts": 1725024600700, "data": {"s": "BTCUSDT", "b": [["59999.8", "2.2"]], "a": [], "u": 107, "seq": 9015}}
{"topic": "orderbook.200.BTCUSDT", "type": "delta", "ts": 1725024600800, "data": {"s": "BTCUSDT", "b": [], "a": [["60000.2", "0"]], "u": 108, "seq": 9016}}
{"topic": "orderbook.200.BTCUSDT", "type": "delta", "ts": 1725024600900, "data": {"s": "BTCUSDT", "b": [["59999.3", "4.0"]], "a": [], "u": 109, "seq": 9020}}
{"topic": "orderbook.200.BTCUSDT", "type": "delta", "ts": 1725024601000, "data": {"s": "BTCUSDT", "b": [], "a": [["60000.3", "5.0"]], "u": 110, "seq": 9021}}
{"topic": "orderbook.200.BTCUSDT", "type": "delta", "ts": 1725024601100, "data": {"s": "BTCUSDT", "b": [["59999.7", "0"]], "a": [], "u": 111, "seq": 9022}}
{"topic": "orderbook.200.BTCUSDT", "type": "delta", "ts": 1725024601200, "data": {"s": "BTCUSDT", "b": [["60000.0", "0.7"]], "a": [], "u": 112, "seq": 9025}}
{"topic": "orderbook.200.BTCUSDT", "type": "delta", "ts": 1725024601300, "data": {"s": "BTCUSDT", "b": [], "a": [["60000.8", "0"]], "u": 113, "seq": 9026}}
{"topic": "orderbook.200.BTCUSDT", "type": "delta", "ts": 1725024601400, "data": {"s": "BTCUSDT", "b": [["59999.6", "1.8"]], "a": [["60000.4", "0.2"]], "u": 114, "seq": 9030}}
{"topic": "orderbook.200.BTCUSDT", "type": "delta", "ts": 1725024601500, "data": {"s": "BTCUSDT", "b": [["59999.2", "0.1"]], "a": [], "u": 115, "seq": 9031}}
{"topic": "orderbook.200.BTCUSDT", "type": "delta", "ts": 1725024601600, "data": {"s": "BTCUSDT", "b": [], "a": [["60000.5", "0"]], "u": 116, "seq": 9033}}
{"topic": "orderbook.200.BTCUSDT", "type": "delta", "ts": 1725024601700, "data": {"s": "BTCUSDT", "b": [["59999.9", "0"]], "a": [], "u": 117, "seq": 9034}}
{"topic": "orderbook.200.BTCUSDT", "type": "delta", "ts": 1725024601800, "data": {"s": "BTCUSDT", "b": [], "a": [["60000.9", "2.4"]], "u": 118, "seq": 9040}}
{"topic": "orderbook.200.BTCUSDT", "type": "delta", "ts": 1725024601900, "data": {"s": "BTCUSDT", "b": [["59999.1", "1.0"]], "a": [], "u": 119, "seq": 9041}}
{"topic": "orderbook.200.BTCUSDT", "type": "delta", "ts": 1725024602000, "data": {"s": "BTCUSDT", "b": [["59999.5", "0"]], "a": [["60000.1", "0.6"]], "u": 120, "seq": 9044}}
